<?xml version="1.0" ?>
<robot xmlns:xacro="http://www.ros.org/wiki/xacro">

    <!-- JOINTS-->
    <joint name="base_joint" type="fixed">
      <parent link="world"/>
      <child link="base_link" />
      <origin xyz="0.0 0.0 0.0" rpy="0.0 0.0 0.0"/>
    </joint>

    <joint name="joint1" type="revolute">
      <parent link="base_link"/>
      <child link="link1"/>
      <origin xyz="0.0 0.0 0.155" rpy="0 0 ${-pi}"/>
      <axis xyz="0 0 1"/>
      <limit effort="123" lower="-2.7925" upper="2.7925" velocity="2.0944"/>
      <dynamics friction="0.05" damping="0.1"/>
    </joint>

    <joint name="joint2" type="revolute">
      <parent link="link1"/>
      <child link="link2"/>
      <origin xyz="0.0 0.03 0.210" rpy="0 0 0"/>
      <axis xyz="0 1 0"/>
      <limit effort="123" lower="-2.2689" upper="2.2689" velocity="2.0944"/>
      <dynamics friction="0.05" damping="0.1"/>
    </joint>

    <joint name="joint3" type="revolute">
      <parent link="link2"/>
      <child link="link3"/>
      <origin xyz="0.0 0.035 0.205" rpy="0 0 0"/>
      <axis xyz="0 0 1"/>
      <limit effort="64" lower="-2.9671" upper="2.9671" velocity="2.4435"/>
      <dynamics friction="0.05" damping="0.1"/>
    </joint>

    <joint name="joint4" type="revolute">
      <parent link="link3"/>
      <child link="link4"/>
      <origin xyz="-0.02 -0.03 0.19" rpy="0 0 ${-pi}"/>
      <axis xyz="0 1 0"/>
      <limit effort="64" lower="-1.8675" upper="2.6878" velocity="2.4435" />
      <dynamics friction="0.05" damping="0.1"/>
    </joint>

    <joint name="joint5" type="revolute">
      <parent link="link4"/>
      <child link="link5"/>
      <origin xyz="-0.02 0.025 0.195" rpy="0 0 ${-pi}"/>
      <axis xyz="0 0 1"/>
      <limit effort="39" lower="-2.9671" upper="2.9671" velocity="4.8869" />
      <dynamics friction="0.05" damping="0.1"/>
    </joint>

    <joint name="joint6" type="revolute">
      <parent link="link5"/>
      <child link="link6"/>
      <origin xyz="0.0 0.03 0.19" rpy="0 0 0"/>
      <axis xyz="0 1 0"/>
      <limit effort="39" lower="-1.3963" upper="4.5379" velocity="4.8869" />
      <dynamics friction="0.05" damping="0.1"/>
    </joint>

    <joint name="joint7" type="revolute">
      <parent link="link6"/>
      <child link="link7"/>
      <origin xyz="-0.055 0.070 0.11" rpy="0 ${-pi/2} 0"/>
      <axis xyz="0 0 1"/>
      <limit effort="39" lower="-2.9671" upper="2.9671" velocity="4.8869" />
      <dynamics friction="0.05" damping="0.1"/>
    </joint>



    <!-- LINKS -->
    <link name="world"/>

    <link name="base_link">
      <inertial>
        <mass value="3.7" />
        <origin rpy="0 0 0" xyz="0.0 -0.0 0.09" />
        <inertia ixx="0.02" ixy="0.0" ixz="0.0" iyy="0.02" iyz="0.0001" izz="0.009" />
      </inertial>
      <visual>
        <origin xyz="0 0 0" rpy="0 0 0"/>
        <geometry>
          <mesh filename="package://my_robot_description/meshes/visual/link0.obj" />
        </geometry>
        
      </visual>
      <collision>
        <origin xyz="0 0 0" rpy="0 0 0"/>
        <geometry>
          <mesh filename="package://my_robot_description/meshes/collision/link0.stl" />
        </geometry>
      </collision>
    </link>

    <link name="link1">
      <inertial>
        <mass value="3.7" />
        <origin rpy="0 0 0" xyz="0.0 0.01 0.15" />
        <inertia ixx="0.03" ixy="0.0" ixz="0.0" iyy="0.03" iyz="0.002" izz="0.008" />
      </inertial>
      <visual>
        <origin xyz="0 0 0" rpy="0 0 0" />
        <geometry>
          <mesh filename="package://my_robot_description/meshes/visual/link1.obj" />
        </geometry>
        
      </visual>
      <collision>
        <origin xyz="0 0 0" rpy="0 0 0" />
        <geometry>
          <mesh filename="package://my_robot_description/meshes/collision/link1.stl" />
        </geometry>
      </collision>
    </link>

    <link name="link2">
      <inertial>
        <mass value="2.7" />
        <origin rpy="0 0 0" xyz="0.0 0.04 0.1" />
        <inertia ixx="0.02" ixy="0.0" ixz="0.0" iyy="0.02" iyz="-0.0003" izz="0.004" />
      </inertial>
      <visual>
        <origin xyz="0 0 0" rpy="0 0 0"/>
        <geometry>
          <mesh filename="package://my_robot_description/meshes/visual/link2.obj" />
        </geometry>
        
      </visual>
      <collision>
        <origin xyz="0 0 0" rpy="0 0 0"/>
        <geometry>
          <mesh filename="package://my_robot_description/meshes/collision/link2.stl" />
        </geometry>
      </collision>
    </link>

    <link name="link3">
      <inertial>
        <mass value="2.4" />
        <origin rpy="0 0 0" xyz="-0.01 -0.0 0.13" />
        <inertia ixx="0.01" ixy="0.00" ixz="-0.001" iyy="0.01" iyz="-0.0007" izz="0.004" />
      </inertial>
      <visual>
        <origin xyz="0 0 0" rpy="0 0 0" />
        <geometry>
          <mesh filename="package://my_robot_description/meshes/visual/link3.obj" />
        </geometry>
        
      </visual>
      <collision>
        <origin xyz="0 0 0" rpy="0 0 0" />
        <geometry>
          <mesh filename="package://my_robot_description/meshes/collision/link3.stl" />
        </geometry>
      </collision>
    </link>

    <link name="link4">
      <inertial>
        <mass value="2.4" />
        <origin rpy="0 0 0" xyz="-0.01 0.03 0.1" />
        <inertia ixx="0.02" ixy="0.00" ixz="-0.002" iyy="0.02" iyz="-0.001" izz="0.003" />
      </inertial>
      <visual>
        <origin xyz="0 0 0" rpy="0 0 0"/>
        <geometry>
          <mesh filename="package://my_robot_description/meshes/visual/link4.obj" />
        </geometry>
        
      </visual>
      <collision>
        <origin xyz="0 0 0" rpy="0 0 0"/>
        <geometry>
          <mesh filename="package://my_robot_description/meshes/collision/link4.stl" />
        </geometry>
      </collision>
    </link>

    <link name="link5">
      <inertial>
        <mass value="2.4" />
        <origin rpy="0 0 0" xyz="0.0 0.0 0.13" />
        <inertia ixx="0.01" ixy="0.0" ixz="0.0" iyy="0.01" iyz="0.001" izz="0.004" />
      </inertial>
      <visual>
        <origin xyz="0 0 0" rpy="0 0 0"/>
        <geometry>
          <mesh filename="package://my_robot_description/meshes/visual/link5.obj" />
        </geometry>
        
      </visual>
      <collision>
        <origin xyz="0 0 0" rpy="0 0 0"/>
        <geometry>
          <mesh filename="package://my_robot_description/meshes/collision/link5.stl" />
        </geometry>
      </collision>
    </link>

    <link name="link6">
      <inertial>
        <mass value="2.1" />
        <origin rpy="0 0 0" xyz="-0.01 0.06 0.07" />
        <inertia ixx="0.01" ixy="-0.000" ixz="-0.001" iyy="0.01" iyz="0.002" izz="0.004" />
      </inertial>
      <visual>
        <origin xyz="0 0 0" rpy="0 0 0"/>
        <geometry>
          <mesh filename="package://my_robot_description/meshes/visual/link6.obj" />
        </geometry>
        
      </visual>
      <collision>
        <origin xyz="0 0 0" rpy="0 0 0"/>
        <geometry>
          <mesh filename="package://my_robot_description/meshes/collision/link6.stl" />
        </geometry>
      </collision>
    </link>

    <link name="link7">
      <inertial>
        <mass value="0.8" />
        <origin rpy="0 0 0" xyz="0.0 0.0 0.03" />
        <inertia ixx="0.001" ixy="0.0" ixz="0.0" iyy="0.001" iyz="0.0" izz="0.001" />
      </inertial>
      <visual>
        <origin xyz="0 0 0" rpy="0 0 0"/>
        <geometry>
          <mesh filename="package://my_robot_description/meshes/visual/link7.obj" />
        </geometry>
        
      </visual>
      <collision>
        <origin xyz="0 0 0" rpy="0 0 0"/>
        <geometry>
          <mesh filename="package://my_robot_description/meshes/collision/link7.stl" />
        </geometry>
      </collision>
    </link>


  <!-- Attach a sensor link -->
    <joint name="sensor_link_joint" type="fixed">
      <origin xyz="0 0 0" rpy="${-pi / 2.0} 0 0"/>
      <parent link="link7"/>
      <child link="sensor_link"/>
    </joint>

    <link name="sensor_link"/>

  <!-- The default end-effector -->
    <joint name="tool0_joint" type="fixed">
      <origin xyz="0 0 0" rpy="0 0 0"/>
      <parent link="sensor_link"/>
      <child link="tool0"/>
    </joint>

    <link name="tool0">
      <visual>
        <origin xyz="0 0 0" rpy="0 0 0" />
        <geometry>
          <sphere radius="0.05"/>
        </geometry>
      </visual>
      <collision>
        <origin xyz="0 0 0" rpy="0 0 0"/>
        <geometry>
          <sphere radius="0.05"/>
        </geometry>
      </collision>
    </link>

</robot>
